Workbook

Sheet ЛБ3
B1: Вариант 23
A2: Дни продаж | B2: мыло | C2: порошок | D2: средство | E2: краска | F2: пена | G2: прибыль | J2: ВЫВОД ИТОГОВ
B3: шт. | C3: шт. | D3: шт. | E3: шт. | F3: шт. | G3: тыс. руб.
A4: 1 | B4: 120 | C4: 19 | D4: 17 | E4: 41 | F4: 19 | G4: 27.429 | J4: Регрессионная статистика
A5: 2 | B5: 73 | C5: 21 | D5: 18 | E5: 41 | F5: 23 | G5: 24.801 | J5: Множественный R | L5: 0.5572
A6: 3 | B6: 77 | C6: 14 | D6: 17 | E6: 41 | F6: 21 | G6: 26.081 | J6: R-квадрат | L6: 0.7465
A7: 4 | B7: 65 | C7: 15 | D7: 21 | E7: 40 | F7: 18 | G7: 23.333 | J7: Нормированный R-квадрат | L7: 0.5170
A8: 5 | B8: 115 | C8: 12 | D8: 19 | E8: 45 | F8: 22 | G8: 27.892 | J8: Стандартная ошибка | L8: 1.286
A9: 6 | B9: 106 | C9: 15 | D9: 26 | E9: 43 | F9: 21 | G9: 27.656 | J9: Наблюдения | L9: 50
A10: 7 | B10: 77 | C10: 16 | D10: 22 | E10: 43 | F10: 21 | G10: 26.288
A11: 8 | B11: 109 | C11: 20 | D11: 18 | E11: 42 | F11: 22 | G11: 28.348 | J11: Дисперсионный анализ
A12: 9 | B12: 101 | C12: 15 | D12: 20 | E12: 40 | F12: 16 | G12: 26.276 | K12: df | L12: SS | M12: MS | N12: F | O12: Значимость F
A13: 10 | B13: 88 | C13: 8 | D13: 19 | E13: 43 | F13: 24 | G13: 27.034 | J13: Регрессия | K13: 5 | L13: 91.547735 | M13: 18.309547 | N13: 11.08598 | O13: 1.3232E-07
A14: 11 | B14: 117 | C14: 25 | D14: 22 | E14: 42 | F14: 23 | G14: 28.198 | J14: Остаток | K14: 44 | L14: 72.738825 | M14: 1.653155
A15: 12 | B15: 82 | C15: 29 | D15: 19 | E15: 44 | F15: 23 | G15: 25.4 | J15: Итого | K15: 49 | L15: 164.286560
A16: 13 | B16: 66 | C16: 17 | D16: 15 | E16: 45 | F16: 19 | G16: 24.777
A17: 14 | B17: 109 | C17: 20 | D17: 23 | E17: 41 | F17: 22 | G17: 27.967 | K17: Коэффициенты | L17: Стандартная ошибка | M17: t-статистика | N17: P-Значение | O17: Нижние 95% | P17: Верхние 95%
A18: 15 | B18: 105 | C18: 20 | D18: 22 | E18: 43 | F18: 22 | G18: 28.24 | J18: Y-пересечение | K18: 7.649389 | L18: 3.603557 | M18: 2.122733 | N18: 0.039440 | O18: 0.386897 | P18: 14.911882
A19: 16 | B19: 113 | C19: 18 | D19: 21 | E19: 44 | F19: 21 | G19: 28.319 | J19: мыло | K19: 0.071344 | L19: 0.007774 | M19: 9.176708 | N19: 0.000000 | O19: 0.055675 | P19: 0.087012
A20: 17 | B20: 68 | C20: 10 | D20: 15 | E20: 44 | F20: 19 | G20: 25.633 | J20: порошок | K20: -0.010543 | L20: 0.023925 | M20: -0.440672 | N20: 0.661608 | O20: -0.058761 | P20: 0.037675
A21: 18 | B21: 93 | C21: 18 | D21: 20 | E21: 39 | F21: 22 | G21: 27.166 | J21: средство | K21: 0.024113 | L21: 0.053055 | M21: 0.454497 | N21: 0.651706 | O21: -0.082812 | P21: 0.131039
A22: 19 | B22: 112 | C22: 23 | D22: 21 | E22: 43 | F22: 21 | G22: 30.269 | J22: краска | K22: 0.253675 | L22: 0.074723 | M22: 3.394879 | N22: 0.001464 | O22: 0.103081 | P22: 0.404269
A23: 20 | B23: 124 | C23: 18 | D23: 22 | E23: 41 | F23: 20 | G23: 27.232 | J23: пена | K23: 0.064749 | L23: 0.069325 | M23: 0.934005 | N23: 0.355399 | O23: -0.074965 | P23: 0.204464
A24: 21 | B24: 116 | C24: 23 | D24: 22 | E24: 42 | F24: 20 | G24: 28.563
A25: 22 | B25: 90 | C25: 12 | D25: 19 | E25: 44 | F25: 17 | G25: 27.537 | J25: корреляция
A26: 23 | B26: 116 | C26: 22 | D26: 27 | E26: 39 | F26: 22 | G26: 27.994 | K26: мыло | L26: порошок | M26: средство | N26: краска | O26: пена | P26: прибыль
A27: 24 | B27: 93 | C27: 18 | D27: 21 | E27: 43 | F27: 21 | G27: 25.981 | J27: мыло | K27: 1
A28: 25 | B28: 93 | C28: 12 | D28: 23 | E28: 42 | F28: 23 | G28: 25.135 | J28: порошок | K28: -0.03 | L28: 1
A29: 26 | B29: 125 | C29: 23 | D29: 20 | E29: 44 | F29: 21 | G29: 29.632 | J29: средство | K29: 0.05 | L29: 0.14 | M29: 1
A30: 27 | B30: 103 | C30: 28 | D30: 19 | E30: 41 | F30: 21 | G30: 25.365 | J30: краска | K30: 0.04 | L30: 0.05 | M30: 0.04 | N30: 1
A31: 28 | B31: 100 | C31: 16 | D31: 19 | E31: 41 | F31: 18 | G31: 25.978 | J31: пена | K31: -0.08 | L31: 0.13 | M31: 0.1 | N31: -0.02 | O31: 1
A32: 29 | B32: 74 | C32: 15 | D32: 24 | E32: 40 | F32: 21 | G32: 24.093 | J32: прибыль | K32: 0.61 | L32: 0.23 | M32: 0.16 | N32: 0.52 | O32: 0.13 | P32: 1
A33: 30 | B33: 125 | C33: 27 | D33: 24 | E33: 40 | F33: 20 | G33: 29.036
A34: 31 | B34: 76 | C34: 16 | D34: 22 | E34: 44 | F34: 20 | G34: 26.545
A35: 32 | B35: 78 | C35: 21 | D35: 18 | E35: 42 | F35: 19 | G35: 26.455
A36: 33 | B36: 88 | C36: 19 | D36: 22 | E36: 43 | F36: 17 | G36: 24.591
A37: 34 | B37: 74 | C37: 10 | D37: 19 | E37: 44 | F37: 22 | G37: 26.381
A38: 35 | B38: 102 | C38: 33 | D38: 26 | E38: 43 | F38: 25 | G38: 28.034
A39: 36 | B39: 90 | C39: 23 | D39: 19 | E39: 43 | F39: 19 | G39: 25.862
A40: 37 | B40: 111 | C40: 25 | D40: 21 | E40: 44 | F40: 21 | G40: 28.659
...

Sheet Лист3
B1: Вариант 23
A2: Дни продаж | B2: мыло | C2: краска | D2: прибыль
A3: 1 | B3: 120 | C3: 41 | D3: 27.506 | I3: ВЫВОД ИТОГОВ
A4: 2 | B4: 73 | C4: 41 | D4: 24.464
A5: 3 | B5: 77 | C5: 41 | D5: 24.752 | I5: Регрессионная статистика
A6: 4 | B6: 65 | C6: 40 | D6: 23.912 | I6: Множественный R | J6: 0.9378
A7: 5 | B7: 115 | C7: 45 | D7: 28.292 | I7: R-квадрат | J7: 0.8794
A8: 6 | B8: 106 | C8: 43 | D8: 27.476 | I8: Нормированный R-квадрат | J8: 0.8743
A9: 7 | B9: 77 | C9: 43 | D9: 25.24 | I9: Стандартная ошибка | J9: 0.5162
A10: 8 | B10: 109 | C10: 42 | D10: 27.332 | I10: Наблюдения | J10: 50
A11: 9 | B11: 101 | C11: 40 | D11: 26.366
A12: 10 | B12: 88 | C12: 43 | D12: 25.982 | I12: Дисперсионный анализ
A13: 11 | B13: 117 | C13: 42 | D13: 27.866 | J13: df | K13: SS | L13: MS | M13: F | N13: Значимость F
A14: 12 | B14: 82 | C14: 44 | D14: 26.23 | I14: Регрессия | J14: 2 | K14: 74.6518 | L14: 37.3259 | M14: 140.147 | N14: 1.37E-20
A15: 13 | B15: 66 | C15: 45 | D15: 25.072 | I15: Остаток | J15: 47 | K15: 12.493 | L15: 0.2658
A16: 14 | B16: 109 | C16: 41 | D16: 27.086 | I16: Итого | J16: 49 | K16: 87.1452
A17: 15 | B17: 105 | C17: 43 | D17: 27.404
A18: 16 | B18: 113 | C18: 44 | D18: 28.29 | J18: Коэффициенты | K18: Стандартная ошибка | L18: t-статистика | M18: P-Значение | N18: Нижние 95% | O18: Верхние 95%
A19: 17 | B19: 68 | C19: 44 | D19: 25.414 | I19: Y-пересечение | J19: 4.720 | K19: 1.3689 | L19: 3.448 | M19: 0.0012 | N19: 1.964 | O19: 7.476
A20: 18 | B20: 93 | C20: 39 | D20: 26.3 | I20: мыло | J20: 0.1543 | K20: 0.0106 | L20: 14.547 | M20: 1.72E-18 | N20: 0.1329 | O20: 0.1757
A21: 19 | B21: 112 | C21: 43 | D21: 27.794 | I21: краска | J21: 0.3047 | K21: 0.0521 | L21: 5.849 | M21: 2.48E-07 | N21: 0.1998 | O21: 0.4096
A22: 20 | B22: 124 | C22: 41 | D22: 27.886
A23: 21 | B23: 116 | C23: 42 | D23: 27.794
A24: 22 | B24: 90 | C24: 44 | D24: 26.716
A25: 23 | B25: 116 | C25: 39 | D25: 27.074
A26: 24 | B26: 93 | C26: 43 | D26: 27.02
A27: 25 | B27: 93 | C27: 42 | D27: 26.774
A28: 26 | B28: 125 | C28: 44 | D28: 28.672
A29: 27 | B29: 103 | C29: 41 | D29: 27.026
A30: 28 | B30: 100 | C30: 41 | D30: 26.81
A31: 29 | B31: 74 | C31: 40 | D31: 24.392
A32: 30 | B32: 125 | C32: 40 | D32: 27.692
A33: 31 | B33: 76 | C33: 44 | D33: 25.702
... A52: 50 | B52: 90 | C52: 43 | D52: 26.716

Sheet CI_Analysis
A1: 95% ДОВЕРИТЕЛЬНЫЕ ИНТЕРВАЛЫ
P2: Вариант 23
A3: ПАРАМЕТРЫ: | O3: Дни продаж | P3: мыло | Q3: краска | R3: прибыль
A4: n | B4: 50 | O4: 1 | P4: 120 | Q4: 41 | R4: 27.506
A5: t-крит (95%, df=48) | B5: 2.0106 | O5: 2 | P5: 73 | Q5: 41 | R5: 24.464
O6: 3 | P6: 77 | Q6: 41 | R6: 24.752
A7: РЕГРЕССИЯ 1: Y = f(Мыло) | D7: Уравнение: Y = a0 + a1*X | O7: 4 | P7: 65 | Q7: 40 | R7: 23.912
A8: a0 (intercept) | B8: =INTERCEPT(R4:R53,P4:P53) -> 20.824393 | O8: 5 | P8: 115 | Q8: 45 | R8: 28.292
A9: a1 (slope) | B9: =SLOPE(Лист3!D3:D52,Лист3!B3:B52) -> 0.059673236 | D9: Уравнение: Y = b0 + b1*X | O9: 6 | P9: 106 | Q9: 43 | R9: 27.476
A10: Se | B10: =STEYX(Лист3!D3:D52,Лист3!B3:B52) -> 0.48338918 | O10: 7 | P10: 77 | Q10: 43 | R10: 25.24
A11: X_mean | B11: =AVERAGE(Лист3!B3:B52) -> 97.54 | O11: 8 | P11: 109 | Q11: 42 | R11: 27.332
A12: SSx | B12: =DEVSQ(Лист3!B3:B52) -> 17774.42 | O12: 9 | P12: 101 | Q12: 40 | R12: 26.366
O13: 10 | P13: 88 | Q13: 43 | R13: 25.982
A14: РЕГРЕССИЯ 2: Y = f(Краска) | O14: 11 | P14: 117 | Q14: 42 | R14: 27.866
A15: b0 (intercept) | B15: =INTERCEPT(Лист3!D3:D52,Лист3!C3:C52) -> 20.892857 | O15: 12 | P15: 82 | Q15: 44 | R15: 26.23
A16: b1 (slope) | B16: =SLOPE(Лист3!D3:D52,Лист3!C3:C52) -> 0.1364989 | O16: 13 | P16: 66 | Q16: 45 | R16: 25.072
A17: Se | B17: =STEYX(Лист3!D3:D52,Лист3!C3:C52) -> 1.2216713 | O17: 14 | P17: 109 | Q17: 41 | R17: 27.086
A18: X_mean | B18: =AVERAGE(Лист3!C3:C52) -> 42.14 | O18: 15 | P18: 105 | Q18: 43 | R18: 27.404
A19: SSx | B19: =DEVSQ(Лист3!C3:C52) -> 154.02 | O19: 16 | P19: 113 | Q19: 44 | R19: 28.29
O20: 17 | P20: 68 | Q20: 44 | R20: 25.414
A21: ГРАФИК 1: Прибыль = f(Мыло) | G21: ГРАФИК 2: Прибыль = f(Краска) | O21: 18 | P21: 93 | Q21: 39 | R21: 26.3
A22: Мыло | B22: Прибыль | C22: Y_pred | D22: CI_low | E22: CI_high | G22: Краска | H22: Прибыль | I22: Y_pred | J22: CI_low | K22: CI_high | O22: 19 | P22: 112 | Q22: 43 | R22: 27.794
A23: {=Лист3!B6} -> 65 | B23: {=Лист3!D6} -> 23.912 | C23: =$B$8+$B$9*A23 -> 24.703153 | D23: =C23-$B$5*$B$10*SQRT(1/$B$4+(A23-$B$11)^2/$B$12) -> 24.428994 | E23: =C23+$B$5*$B$10*SQRT(1/$B$4+(A23-$B$11)^2/$B$12) -> 24.977311 | G23: {=Лист3!C40} -> 38 | H23: {=Лист3!D40} -> 24.002 | I23: =$B$15+$B$16*G23 -> 26.079815 | J23: =I23-$B$5*$B$17*SQRT(1/$B$4+(G23-$B$18)^2/$B$19) -> 25.189831 | K23: =I23+$B$5*$B$17*SQRT(1/$B$4+(G23-$B$18)^2/$B$19) -> 26.969798 | O23: 20 | P23: 124 | Q23: 41 | R23: 27.886
A24: {=Лист3!B15} -> 66 | B24: {=Лист3!D15} -> 25.072 | C24: =$B$8+$B$9*A24 -> 24.762826 | D24: =C24-$B$5*$B$10*SQRT(1/$B$4+(A24-$B$11)^2/$B$12) -> 24.49495 | E24: =C24+$B$5*$B$10*SQRT(1/$B$4+(A24-$B$11)^2/$B$12) -> 25.030702 | G24: {=Лист3!C20} -> 39 | H24: {=Лист3!D20} -> 26.3 | I24: =$B$15+$B$16*G24 -> 26.216313 | J24: =I24-$B$5*$B$17*SQRT(1/$B$4+(G24-$B$18)^2/$B$19) -> 25.504348 | K24: =I24+$B$5*$B$17*SQRT(1/$B$4+(G24-$B$18)^2/$B$19) -> 26.928278 | O24: 21 | P24: 116 | Q24: 42 | R24: 27.794
A25: {=Лист3!B49} -> 67 | B25: {=Лист3!D49} -> 25.144 | C25: =$B$8+$B$9*A25 -> 24.822499 | D25: =C25-$B$5*$B$10*SQRT(1/$B$4+(A25-$B$11)^2/$B$12) -> 24.560854 | E25: =C25+$B$5*$B$10*SQRT(1/$B$4+(A25-$B$11)^2/$B$12) -> 25.084145 | G25: {=Лист3!C25} -> 39 | H25: {=Лист3!D25} -> 27.074 | I25: =$B$15+$B$16*G25 -> 26.216313 | J25: =I25-$B$5*$B$17*SQRT(1/$B$4+(G25-$B$18)^2/$B$19) -> 25.504348 | K25: =I25+$B$5*$B$17*SQRT(1/$B$4+(G25-$B$18)^2/$B$19) -> 26.928278 | O25: 22 | P25: 90 | Q25: 44 | R25: 26.716
A26: {=Лист3!B19} -> 68 | B26: {=Лист3!D19} -> 25.414 | C26: =$B$8+$B$9*A26 -> 24.882173 | D26: =C26-$B$5*$B$10*SQRT(1/$B$4+(A26-$B$11)^2/$B$12) -> 24.626702 | E26: =C26+$B$5*$B$10*SQRT(1/$B$4+(A26-$B$11)^2/$B$12) -> 25.137644 | G26: {=Лист3!C6} -> 40 | H26: {=Лист3!D6} -> 23.912 | I26: =$B$15+$B$16*G26 -> 26.352812 | J26: =I26-$B$5*$B$17*SQRT(1/$B$4+(G26-$B$18)^2/$B$19) -> 25.805033 | K26: =I26+$B$5*$B$17*SQRT(1/$B$4+(G26-$B$18)^2/$B$19) -> 26.900592 | O26: 23 | P26: 116 | Q26: 39 | R26: 27.074
A27: {=Лист3!B4} -> 73 | B27: {=Лист3!D4} -> 24.464 | C27: =$B$8+$B$9*A27 -> 25.180539 | D27: =C27-$B$5*$B$10*SQRT(1/$B$4+(A27-$B$11)^2/$B$12) -> 24.954939 | E27: =C27+$B$5*$B$10*SQRT(1/$B$4+(A27-$B$11)^2/$B$12) -> 25.406139 | G27: {=Лист3!C11} -> 40 | H27: {=Лист3!D11} -> 26.366 | I27: =$B$15+$B$16*G27 -> 26.352812 | J27: =I27-$B$5*$B$17*SQRT(1/$B$4+(G27-$B$18)^2/$B$19) -> 25.805033 | K27: =I27+$B$5*$B$17*SQRT(1/$B$4+(G27-$B$18)^2/$B$19) -> 26.900592 | O27: 24 | P27: 93 | Q27: 43 | R27: 27.02
A28: {=Лист3!B40} -> 73 | B28: {=Лист3!D40} -> 24.002 | C28: =$B$8+$B$9*A28 -> 25.180539 | D28: =C28-$B$5*$B$10*SQRT(1/$B$4+(A28-$B$11)^2/$B$12) -> 24.954939 | E28: =C28+$B$5*$B$10*SQRT(1/$B$4+(A28-$B$11)^2/$B$12) -> 25.406139 | G28: {=Лист3!C31} -> 40 | H28: {=Лист3!D31} -> 24.392 | I28: =$B$15+$B$16*G28 -> 26.352812 | J28: =I28-$B$5*$B$17*SQRT(1/$B$4+(G28-$B$18)^2/$B$19) -> 25.805033 | K28: =I28+$B$5*$B$17*SQRT(1/$B$4+(G28-$B$18)^2/$B$19) -> 26.900592 | O28: 25 | P28: 93 | Q28: 42 | R28: 26.774
A29: {=Лист3!B31} -> 74 | B29: {=Лист3!D31} -> 24.392 | C29: =$B$8+$B$9*A29 -> 25.240212 | D29: =C29-$B$5*$B$10*SQRT(1/$B$4+(A29-$B$11)^2/$B$12) -> 25.020348 | E29: =C29+$B$5*$B$10*SQRT(1/$B$4+(A29-$B$11)^2/$B$12) -> 25.460076 | G29: {=Лист3!C32} -> 40 | H29: {=Лист3!D32} -> 27.692 | I29: =$B$15+$B$16*G29 -> 26.352812 | J29: =I29-$B$5*$B$17*SQRT(1/$B$4+(G29-$B$18)^2/$B$19) -> 25.805033 | K29: =I29+$B$5*$B$17*SQRT(1/$B$4+(G29-$B$18)^2/$B$19) -> 26.900592 | O29: 26 | P29: 125 | Q29: 44 | R29: 28.672
A30: {=Лист3!B36} -> 74 | B30: {=Лист3!D36} -> 25.63 | C30: =$B$8+$B$9*A30 -> 25.240212 | D30: =C30-$B$5*$B$10*SQRT(1/$B$4+(A30-$B$11)^2/$B$12) -> 25.020348 | E30: =C30+$B$5*$B$10*SQRT(1/$B$4+(A30-$B$11)^2/$B$12) -> 25.460076 | G30: {=Лист3!C43} -> 40 | H30: {=Лист3!D43} -> 27.26 | I30: =$B$15+$B$16*G30 -> 26.352812 | J30: =I30-$B$5*$B$17*SQRT(1/$B$4+(G30-$B$18)^2/$B$19) -> 25.805033 | K30: =I30+$B$5*$B$17*SQRT(1/$B$4+(G30-$B$18)^2/$B$19) -> 26.900592 | O30: 27 | P30: 103 | Q30: 41 | R30: 27.026
A31: {=Лист3!B44} -> 74 | B31: {=Лист3!D44} -> 25.112 | C31: =$B$8+$B$9*A31 -> 25.240212 | D31: =C31-$B$5*$B$10*SQRT(1/$B$4+(A31-$B$11)^2/$B$12) -> 25.020348 | E31: =C31+$B$5*$B$10*SQRT(1/$B$4+(A31-$B$11)^2/$B$12) -> 25.460076 | G31: {=Лист3!C46} -> 40 | H31: {=Лист3!D46} -> 27.31 | I31: =$B$15+$B$16*G31 -> 26.352812 | J31: =I31-$B$5*$B$17*SQRT(1/$B$4+(G31-$B$18)^2/$B$19) -> 25.805033 | K31: =I31+$B$5*$B$17*SQRT(1/$B$4+(G31-$B$18)^2/$B$19) -> 26.900592 | O31: 28 | P31: 100 | Q31: 41 | R31: 26.81
A32: {=Лист3!B33} -> 76 | B32: {=Лист3!D33} -> 25.702 | C32: =$B$8+$B$9*A32 -> 25.359558 | D32: =C32-$B$5*$B$10*SQRT(1/$B$4+(A32-$B$11)^2/$B$12) -> 25.150875 | E32: =C32+$B$5*$B$10*SQRT(1/$B$4+(A32-$B$11)^2/$B$12) -> 25.568242 | G32: {=Лист3!C48} -> 40 | H32: {=Лист3!D48} -> 27.116 | I32: =$B$15+$B$16*G32 -> 26.352812 | J32: =I32-$B$5*$B$17*SQRT(1/$B$4+(G32-$B$18)^2/$B$19) -> 25.805033 | K32: =I32+$B$5*$B$17*SQRT(1/$B$4+(G32-$B$18)^2/$B$19) -> 26.900592 | O32: 29 | P32: 74 | Q32: 40 | R32: 24.392
A33: {=Лист3!B5} -> 77 | B33: {=Лист3!D5} -> 24.752 | C33: =$B$8+$B$9*A33 -> 25.419232 | D33: =C33-$B$5*$B$10*SQRT(1/$B$4+(A33-$B$11)^2/$B$12) -> 25.215977 | E33: =C33+$B$5*$B$10*SQRT(1/$B$4+(A33-$B$11)^2/$B$12) -> 25.622487 | G33: {=Лист3!C50} -> 40 | H33: {=Лист3!D50} -> 26 | I33: =$B$15+$B$16*G33 -> 26.352812 | J33: =I33-$B$5*$B$17*SQRT(1/$B$4+(G33-$B$18)^2/$B$19) -> 25.805033 | K33: =I33+$B$5*$B$17*SQRT(1/$B$4+(G33-$B$18)^2/$B$19) -> 26.900592 | O33: 30 | P33: 125 | Q33: 40 | R33: 27.692
A34: {=Лист3!B9} -> 77 | B34: {=Лист3!D9} -> 25.24 | C34: =$B$8+$B$9*A34 -> 25.419232 | D34: =C34-$B$5*$B$10*SQRT(1/$B$4+(A34-$B$11)^2/$B$12) -> 25.215977 | E34: =C34+$B$5*$B$10*SQRT(1/$B$4+(A34-$B$11)^2/$B$12) -> 25.622487 | G34: {=Лист3!C3} -> 41 | H34: {=Лист3!D3} -> 27.506 | I34: =$B$15+$B$16*G34 -> 26.489311 | J34: =I34-$B$5*$B$17*SQRT(1/$B$4+(G34-$B$18)^2/$B$19) -> 26.075094 | K34: =I34+$B$5*$B$17*SQRT(1/$B$4+(G34-$B$18)^2/$B$19) -> 26.903529 | O34: 31 | P34: 76 | Q34: 44 | R34: 25.702
A35: {=Лист3!B34} -> 78 | B35: {=Лист3!D34} -> 25.316 | C35: =$B$8+$B$9*A35 -> 25.478905 | D35: =C35-$B$5*$B$10*SQRT(1/$B$4+(A35-$B$11)^2/$B$12) -> 25.280959 | E35: =C35+$B$5*$B$10*SQRT(1/$B$4+(A35-$B$11)^2/$B$12) -> 25.676851 | G35: {=Лист3!C4} -> 41 | H35: {=Лист3!D4} -> 24.464 | I35: =$B$15+$B$16*G35 -> 26.489311 | J35: =I35-$B$5*$B$17*SQRT(1/$B$4+(G35-$B$18)^2/$B$19) -> 26.075094 | K35: =I35+$B$5*$B$17*SQRT(1/$B$4+(G35-$B$18)^2/$B$19) -> 26.903529 | O35: 32 | P35: 78 | Q35: 42 | R35: 25.316
A36: {=Лист3!B14} -> 82 | B36: {=Лист3!D14} -> 26.23 | C36: =$B$8+$B$9*A36 -> 25.717598 | D36: =C36-$B$5*$B$10*SQRT(1/$B$4+(A36-$B$11)^2/$B$12) -> 25.539481 | E36: =C36+$B$5*$B$10*SQRT(1/$B$4+(A36-$B$11)^2/$B$12) -> 25.895715 | G36: {=Лист3!C5} -> 41 | H36: {=Лист3!D5} -> 24.752 | I36: =$B$15+$B$16*G36 -> 26.489311 | J36: =I36-$B$5*$B$17*SQRT(1/$B$4+(G36-$B$18)^2/$B$19) -> 26.075094 | K36: =I36+$B$5*$B$17*SQRT(1/$B$4+(G36-$B$18)^2/$B$19) -> 26.903529 | O36: 33 | P36: 88 | Q36: 43 | R36: 25.982
A37: {=Лист3!B51} -> 83 | B37: {=Лист3!D51} -> 26.402 | C37: =$B$8+$B$9*A37 -> 25.777271 | D37: =C37-$B$5*$B$10*SQRT(1/$B$4+(A37-$B$11)^2/$B$12) -> 25.6037 | E37: =C37+$B$5*$B$10*SQRT(1/$B$4+(A37-$B$11)^2/$B$12) -> 25.950843 | G37: {=Лист3!C16} -> 41 | H37: {=Лист3!D16} -> 27.086 | I37: =$B$15+$B$16*G37 -> 26.489311 | J37: =I37-$B$5*$B$17*SQRT(1/$B$4+(G37-$B$18)^2/$B$19) -> 26.075094 | K37: =I37+$B$5*$B$17*SQRT(1/$B$4+(G37-$B$18)^2/$B$19) -> 26.903529 | O37: 34 | P37: 74 | Q37: 44 | R37: 25.63
A38: {=Лист3!B12} -> 88 | B38: {=Лист3!D12} -> 25.982 | C38: =$B$8+$B$9*A38 -> 26.075637 | D38: =C38-$B$5*$B$10*SQRT(1/$B$4+(A38-$B$11)^2/$B$12) -> 25.921597 | E38: =C38+$B$5*$B$10*SQRT(1/$B$4+(A38-$B$11)^2/$B$12) -> 26.229678 | G38: {=Лист3!C22} -> 41 | H38: {=Лист3!D22} -> 27.886 | I38: =$B$15+$B$16*G38 -> 26.489311 | J38: =I38-$B$5*$B$17*SQRT(1/$B$4+(G38-$B$18)^2/$B$19) -> 26.075094 | K38: =I38+$B$5*$B$17*SQRT(1/$B$4+(G38-$B$18)^2/$B$19) -> 26.903529 | O38: 35 | P38: 102 | Q38: 43 | R38: 27.26
A39: {=Лист3!B35} -> 88 | B39: {=Лист3!D35} -> 25.982 | C39: =$B$8+$B$9*A39 -> 26.075637 | D39: =C39-$B$5*$B$10*SQRT(1/$B$4+(A39-$B$11)^2/$B$12) -> 25.921597 | E39: =C39+$B$5*$B$10*SQRT(1/$B$4+(A39-$B$11)^2/$B$12) -> 26.229678 | G39: {=Лист3!C29} -> 41 | H39: {=Лист3!D29} -> 27.026 | I39: =$B$15+$B$16*G39 -> 26.489311 | J39: =I39-$B$5*$B$17*SQRT(1/$B$4+(G39-$B$18)^2/$B$19) -> 26.075094 | K39: =I39+$B$5*$B$17*SQRT(1/$B$4+(G39-$B$18)^2/$B$19) -> 26.903529 | O39: 36 | P39: 90 | Q39: 43 | R39: 26.47
A40: {=Лист3!B24} -> 90 | B40: {=Лист3!D24} -> 26.716 | C40: =$B$8+$B$9*A40 -> 26.194984 | D40: =C40-$B$5*$B$10*SQRT(1/$B$4+(A40-$B$11)^2/$B$12) -> 26.046953 | E40: =C40+$B$5*$B$10*SQRT(1/$B$4+(A40-$B$11)^2/$B$12) -> 26.343015 | G40: {=Лист3!C30} -> 41 | H40: {=Лист3!D30} -> 26.81 | I40: =$B$15+$B$16*G40 -> 26.489311 | J40: =I40-$B$5*$B$17*SQRT(1/$B$4+(G40-$B$18)^2/$B$19) -> 26.075094 | K40: =I40+$B$5*$B$17*SQRT(1/$B$4+(G40-$B$18)^2/$B$19) -> 26.903529 | O40: 37 | P40: 111 | Q40: 44 | R40: 28.046
...
